.EF.
======================================================================
ERROR: test_dummy_exception (testrunner.tests.test_views.ViewsTestCase)
----------------------------------------------------------------------
Traceback (most recent call last):
  File "/Users/paulcooper/Documents/GitHub/pbchallenge/testrunner/tests/test_views.py", line 19, in test_dummy_exception
    raise TypeError
TypeError

======================================================================
FAIL: test_dummy_fail (testrunner.tests.test_views.ViewsTestCase)
----------------------------------------------------------------------
Traceback (most recent call last):
  File "/Users/paulcooper/Documents/GitHub/pbchallenge/testrunner/tests/test_views.py", line 16, in test_dummy_fail
    self.assertTrue(False)
AssertionError: False is not true

----------------------------------------------------------------------
Ran 4 tests in 40.010s

FAILED (failures=1, errors=1)
Creating test database for alias 'default'...
System check identified no issues (0 silenced).
Destroying test database for alias 'default'...
